2023-07-12 10:33:03,859 INFO    StreamThr :14748 [internal.py:wandb_internal():86] W&B internal server running at pid: 14748, started at: 2023-07-12 10:33:03.858586
2023-07-12 10:33:03,861 DEBUG   HandlerThread:14748 [handler.py:handle_request():144] handle_request: status
2023-07-12 10:33:03,919 INFO    WriterThread:14748 [datastore.py:open_for_write():85] open: E:\rk3399pro开发板资料\yolov5-code-main\wandb\run-20230712_103303-ctbwr956\run-ctbwr956.wandb
2023-07-12 10:33:03,920 DEBUG   SenderThread:14748 [sender.py:send():375] send: header
2023-07-12 10:33:03,920 DEBUG   SenderThread:14748 [sender.py:send():375] send: run
2023-07-12 10:33:03,932 INFO    SenderThread:14748 [sender.py:_maybe_setup_resume():761] checking resume status for None/train/ctbwr956
2023-07-12 10:33:07,386 INFO    SenderThread:14748 [retry.py:__call__():172] Retry attempt failed:
Traceback (most recent call last):
  File "D:\LZW\Anaconda3\envs\yolov5-v2\lib\site-packages\urllib3\connectionpool.py", line 700, in urlopen
    self._prepare_proxy(conn)
  File "D:\LZW\Anaconda3\envs\yolov5-v2\lib\site-packages\urllib3\connectionpool.py", line 996, in _prepare_proxy
    conn.connect()
  File "D:\LZW\Anaconda3\envs\yolov5-v2\lib\site-packages\urllib3\connection.py", line 369, in connect
    self.sock = conn = self._connect_tls_proxy(hostname, conn)
  File "D:\LZW\Anaconda3\envs\yolov5-v2\lib\site-packages\urllib3\connection.py", line 504, in _connect_tls_proxy
    socket = ssl_wrap_socket(
  File "D:\LZW\Anaconda3\envs\yolov5-v2\lib\site-packages\urllib3\util\ssl_.py", line 453, in ssl_wrap_socket
    ssl_sock = _ssl_wrap_socket_impl(sock, context, tls_in_tls)
  File "D:\LZW\Anaconda3\envs\yolov5-v2\lib\site-packages\urllib3\util\ssl_.py", line 495, in _ssl_wrap_socket_impl
    return ssl_context.wrap_socket(sock)
  File "D:\LZW\Anaconda3\envs\yolov5-v2\lib\ssl.py", line 500, in wrap_socket
    return self.sslsocket_class._create(
  File "D:\LZW\Anaconda3\envs\yolov5-v2\lib\ssl.py", line 1040, in _create
    self.do_handshake()
  File "D:\LZW\Anaconda3\envs\yolov5-v2\lib\ssl.py", line 1309, in do_handshake
    self._sslobj.do_handshake()
OSError: [Errno 0] Error

During handling of the above exception, another exception occurred:

Traceback (most recent call last):
  File "D:\LZW\Anaconda3\envs\yolov5-v2\lib\site-packages\requests\adapters.py", line 489, in send
    resp = conn.urlopen(
  File "D:\LZW\Anaconda3\envs\yolov5-v2\lib\site-packages\urllib3\connectionpool.py", line 787, in urlopen
    retries = retries.increment(
  File "D:\LZW\Anaconda3\envs\yolov5-v2\lib\site-packages\urllib3\util\retry.py", line 592, in increment
    raise MaxRetryError(_pool, url, error or ResponseError(cause))
urllib3.exceptions.MaxRetryError: HTTPSConnectionPool(host='api.wandb.ai', port=443): Max retries exceeded with url: /graphql (Caused by ProxyError('Cannot connect to proxy.', OSError(0, 'Error')))

During handling of the above exception, another exception occurred:

Traceback (most recent call last):
  File "D:\LZW\Anaconda3\envs\yolov5-v2\lib\site-packages\wandb\sdk\lib\retry.py", line 131, in __call__
    result = self._call_fn(*args, **kwargs)
  File "D:\LZW\Anaconda3\envs\yolov5-v2\lib\site-packages\wandb\sdk\internal\internal_api.py", line 285, in execute
    return self.client.execute(*args, **kwargs)  # type: ignore
  File "D:\LZW\Anaconda3\envs\yolov5-v2\lib\site-packages\wandb\vendor\gql-0.2.0\wandb_gql\client.py", line 52, in execute
    result = self._get_result(document, *args, **kwargs)
  File "D:\LZW\Anaconda3\envs\yolov5-v2\lib\site-packages\wandb\vendor\gql-0.2.0\wandb_gql\client.py", line 60, in _get_result
    return self.transport.execute(document, *args, **kwargs)
  File "D:\LZW\Anaconda3\envs\yolov5-v2\lib\site-packages\wandb\sdk\lib\gql_request.py", line 55, in execute
    request = self.session.post(self.url, **post_args)
  File "D:\LZW\Anaconda3\envs\yolov5-v2\lib\site-packages\requests\sessions.py", line 635, in post
    return self.request("POST", url, data=data, json=json, **kwargs)
  File "D:\LZW\Anaconda3\envs\yolov5-v2\lib\site-packages\requests\sessions.py", line 587, in request
    resp = self.send(prep, **send_kwargs)
  File "D:\LZW\Anaconda3\envs\yolov5-v2\lib\site-packages\requests\sessions.py", line 701, in send
    r = adapter.send(request, **kwargs)
  File "D:\LZW\Anaconda3\envs\yolov5-v2\lib\site-packages\requests\adapters.py", line 559, in send
    raise ProxyError(e, request=request)
requests.exceptions.ProxyError: HTTPSConnectionPool(host='api.wandb.ai', port=443): Max retries exceeded with url: /graphql (Caused by ProxyError('Cannot connect to proxy.', OSError(0, 'Error')))
2023-07-12 10:33:08,937 DEBUG   HandlerThread:14748 [handler.py:handle_request():144] handle_request: keepalive
2023-07-12 10:33:14,001 DEBUG   HandlerThread:14748 [handler.py:handle_request():144] handle_request: keepalive
2023-07-12 10:33:19,047 DEBUG   HandlerThread:14748 [handler.py:handle_request():144] handle_request: keepalive
2023-07-12 10:33:24,103 DEBUG   HandlerThread:14748 [handler.py:handle_request():144] handle_request: keepalive
2023-07-12 10:33:29,139 DEBUG   HandlerThread:14748 [handler.py:handle_request():144] handle_request: keepalive
2023-07-12 10:33:34,188 DEBUG   HandlerThread:14748 [handler.py:handle_request():144] handle_request: keepalive
2023-07-12 10:33:39,219 DEBUG   HandlerThread:14748 [handler.py:handle_request():144] handle_request: keepalive
2023-07-12 10:33:44,280 DEBUG   HandlerThread:14748 [handler.py:handle_request():144] handle_request: keepalive
2023-07-12 10:33:49,358 DEBUG   HandlerThread:14748 [handler.py:handle_request():144] handle_request: keepalive
2023-07-12 10:33:54,389 DEBUG   HandlerThread:14748 [handler.py:handle_request():144] handle_request: keepalive
2023-07-12 10:33:59,421 DEBUG   HandlerThread:14748 [handler.py:handle_request():144] handle_request: keepalive
2023-07-12 10:34:04,466 DEBUG   HandlerThread:14748 [handler.py:handle_request():144] handle_request: cancel
2023-07-12 10:34:04,466 DEBUG   HandlerThread:14748 [handler.py:handle_request():144] handle_request: cancel
2023-07-12 10:34:04,467 DEBUG   SenderThread:14748 [sender.py:send():384] Record cancelled: run
2023-07-12 10:34:04,467 DEBUG   HandlerThread:14748 [handler.py:handle_request():144] handle_request: status_report
2023-07-12 10:34:04,602 DEBUG   HandlerThread:14748 [handler.py:handle_request():144] handle_request: shutdown
2023-07-12 10:34:04,602 INFO    HandlerThread:14748 [handler.py:finish():845] shutting down handler
2023-07-12 10:34:05,482 INFO    WriterThread:14748 [datastore.py:close():298] close: E:\rk3399pro开发板资料\yolov5-code-main\wandb\run-20230712_103303-ctbwr956\run-ctbwr956.wandb
2023-07-12 10:34:05,482 INFO    SenderThread:14748 [sender.py:finish():1550] shutting down sender
